<?xml version="1.0"?>
<robot xmlns:xacro="http://www.ros.org/wiki/xacro">

    <xacro:include filename='inertial_macros.xacro'/>

    <material name="white">
        <color rgba="1 1 1 1"/>
    </material>

    <material name="orange">
        <color rgba="1 0.3 0.1 1"/>
    </material>

    <material name="blue">
        <color rgba="0.2 0.2 1 1"/>
    </material>

    <material name="black">
        <color rgba="0 0 0 1"/>
    </material>

    <!-- BASE LINK -->
    <link name="base_link">

    </link>

    <!-- CHASSIS -->
    <!-- Bottom plate .125" not included -->
    <!-- 
        Weight of entire chassis including hubs and bottom
        in kg is:
    -->
    <joint name="chassis_joint" type="fixed">
        <parent link="base_link"/>
        <child link="chassis"/>
        <origin xyz="-0.24765 0 -0.03175"/>
    </joint>

    <link name="chassis">
        <visual>
            <origin xyz="0.24765 0 0.03175"/>
            <geometry>
                <box size=".4953 .4064 .0635"/>
            </geometry>
            <material name="white"/>
        </visual>
        <collision>
            <origin xyz="0.24765 0 0.03175"/>
            <geometry>
                <box size=".4953 .4064 .0635"/>
            </geometry>
        </collision>
        <xacro:inertial_box mass="0.5" x="0.4953" y="0.4046" z="0.0635">
            <origin xyz="0.24765 0 0.03175" rpy="0 0 0"/>
        </xacro:inertial_box>
    </link>

    <gazebo reference="chassis">
        <material>Gazebo/White</material>
    </gazebo>

    <!-- FRONT HUB-->
    <joint name="front_hub_joint" type="fixed">
        <parent link="base_link"/>
        <child link="front_hub"/>
        <origin xyz="0.19685 0 0" rpy="${pi/2} 0 0"/>
    </joint>

    <link name="front_hub">
        <visual>
            <origin xyz="0 0 0"/>
            <geometry>
                <cylinder radius="0.0254" length="0.4445"/>
            </geometry>
            <material name="white"/>
        </visual>
    </link>

    <gazebo reference="front_hub_joint">
        <material>Gazebo/White</material>
    </gazebo>

    <!-- BACK HUB-->
    <joint name="back_hub_joint" type="fixed">
        <parent link="base_link"/>
        <child link="back_hub"/>
        <origin xyz="-0.19685 0 0" rpy="${pi/2} 0 0"/>
    </joint>

    <link name="back_hub">
        <visual>
            <origin xyz="0 0 0"/>
            <geometry>
                <cylinder radius="0.0254" length="0.4445"/>
            </geometry>
            <material name="white"/>
        </visual>
    </link>

    <gazebo reference="back_hub_joint">
        <material>Gazebo/White</material>
    </gazebo>

    <!-- FRONT LEFT WHEEL LINK -->
    <!-- Weight of each wheel: kg-->
    <joint name="front_left_wheel_joint" type="continuous">
        <parent link="base_link"/>
        <child link="front_left_wheel"/>
        <origin xyz="0.19685 0.22225 0" rpy="-${pi/2} 0 0"/>
        <axis xyz="0 0 1"/>
    </joint>

    <link name="front_left_wheel">
        <visual>
            <origin xyz="0 0 0.0425"/>
            <geometry>
                <cylinder radius="0.130" length=".085"/>
            </geometry>
            <material name="blue"/>
        </visual>
        <collision>
            <origin xyz="0 0 0.0425"/>
            <geometry>
                <cylinder radius="0.130" length=".085"/>
            </geometry>
        </collision>
        <xacro:inertial_cylinder mass="0.5" length=".085" radius="0.130">
            <origin xyz="0 0 0.0425" rpy="0 0 0"/>
        </xacro:inertial_cylinder>
    </link>

    <gazebo reference="front_left_wheel">
        <material>Gazebo/Blue</material>
    </gazebo>

    <!-- BACK LEFT WHEEL LINK -->
    <joint name="back_left_wheel_joint" type="continuous">
        <parent link="base_link"/>
        <child link="back_left_wheel"/>
        <origin xyz="-0.19685 0.22225 0" rpy="-${pi/2} 0 0"/>
        <axis xyz="0 0 1"/>
    </joint>

    <link name="back_left_wheel">
        <visual>
            <origin xyz="0 0 0.0425"/>
            <geometry>
                <cylinder radius="0.130" length=".085"/>
            </geometry>
            <material name="blue"/>
        </visual>
        <collision>
            <origin xyz="0 0 0.0425"/>
            <geometry>
                <cylinder radius="0.130" length=".085"/>
            </geometry>
        </collision>
        <xacro:inertial_cylinder mass="0.5" length=".085" radius="0.130">
            <origin xyz="0 0 0.0425" rpy="0 0 0"/>
        </xacro:inertial_cylinder>
    </link>

    <gazebo reference="back_left_wheel">
        <material>Gazebo/Blue</material>
    </gazebo>

    <!-- FRONT RIGHT WHEEL LINK -->
    <joint name="front_right_wheel_joint" type="continuous">
        <parent link="base_link"/>
        <child link="front_right_wheel"/>
        <origin xyz="0.19685 -0.22225 0" rpy="${pi/2} 0 0"/>
        <axis xyz="0 0 -1"/>
    </joint>

    <link name="front_right_wheel">
        <visual>
            <origin xyz="0 0 0.0425"/>
            <geometry>
                <cylinder radius="0.130" length=".085"/>
            </geometry>
            <material name="blue"/>
        </visual>
        <collision>
            <origin xyz="0 0 0.0425"/>
            <geometry>
                <cylinder radius="0.130" length=".085"/>
            </geometry>
        </collision>
        <xacro:inertial_cylinder mass="0.5" length=".085" radius="0.130">
            <origin xyz="0 0 0.0425" rpy="0 0 0"/>
        </xacro:inertial_cylinder>
    </link>

    <gazebo reference="front_right_wheel">
        <material>Gazebo/Blue</material>
    </gazebo>
    
    <!-- BACK RIGHT WHEEL LINK -->
    <joint name="back_right_wheel_joint" type="continuous">
        <parent link="base_link"/>
        <child link="back_right_wheel"/>
        <origin xyz="-0.19685 -0.22225 0" rpy="${pi/2} 0 0"/>
        <axis xyz="0 0 -1"/>
    </joint>

    <link name="back_right_wheel">
        <visual>
            <origin xyz="0 0 0.0425"/>
            <geometry>
                <cylinder radius="0.130" length=".085"/>
            </geometry>
            <material name="blue"/>
        </visual>
        <collision>
            <origin xyz="0 0 0.0425"/>
            <geometry>
                <cylinder radius="0.130" length=".085"/>
            </geometry>
        </collision>
        <xacro:inertial_cylinder mass="0.5" length=".085" radius="0.130">
            <origin xyz="0 0 0.0425" rpy="0 0 0"/>
        </xacro:inertial_cylinder>
    </link>

    <gazebo reference="back_right_wheel">
        <material>Gazebo/Blue</material>
    </gazebo>
</robot>